<?xml version="1.0"?>
<sdf version="1.5">
  <model name="spikebot">
          
	<!-- <static> false </static> -->

	<link name='chassis'>
            <pose>0 0 .10 0 0 0</pose>
             <collision name='collision'>
              <geometry>
                <box>
                  <size>.38 .15 .10</size>
                </box>
              </geometry>
            </collision>
      <inertial>
        <mass>30</mass>
        <pose> 0 0 0 0 0 0</pose>
        <inertia>
          <ixx>2.2343</ixx>
          <ixy>-0.023642</ixy>
          <ixz>0.275174</ixz>
          <iyy>3.42518</iyy>
          <iyz>0.00239624</iyz>
          <izz>2.1241</izz>
        </inertia>
      </inertial>
	<visual name='visual'>
              <geometry>
                <box>
                  <size>.38 .15 .10</size>
                </box>
              </geometry>
            </visual>
          </link>
          
            

	<link name='connector'>
            <pose>-0.08 0.0 .15 0 0 0</pose>
             <collision name='connector_collision'>
              <geometry>
                <box>
                  <size>.30 .15 .05</size>
                </box>
              </geometry>
            </collision>
	<inertial>
        <mass>33.855</mass>
        <pose> 0 0 0 0 0 0</pose>
        <inertia>
          <ixx>2.2343</ixx>
          <ixy>-0.023642</ixy>
          <ixz>0.275174</ixz>
          <iyy>3.42518</iyy>
          <iyz>0.00239624</iyz>
          <izz>2.1241</izz>
        </inertia>
      </inertial>
	<visual name='connector'>
              <geometry>
                <box>
                  <size>.30 .15 .10</size>
                </box>
              </geometry>
            </visual>
          </link>
      <joint type="fixed" name="chassis_connector_hinge">
        <pose>0 0 0.03 0 0 0</pose>
        <child>connector</child>
        <parent>chassis</parent>
        <axis>
          <xyz>1 1 1</xyz>
        </axis>
      </joint>
          
          

	<link name='spinnaker'>
            <pose>-0.08 0 .20 0 0 0</pose>
	    <collision name='spinnaker_collision'>
              <geometry>
                <box>
                  <size>.30 .30 .05</size>
                </box>
              </geometry>
            </collision>
	<inertial>
        <mass>33.855</mass>
        <pose> 0 0 0 0 0 0</pose>
        <inertia>
          <ixx>2.2343</ixx>
          <ixy>-0.023642</ixy>
          <ixz>0.275174</ixz>
          <iyy>3.42518</iyy>
          <iyz>0.00239624</iyz>
          <izz>2.1241</izz>
        </inertia>
      </inertial>
	<visual name='spinnaker'>
              <geometry>
                <box>
                  <size>.30 .30 .05</size>
                </box>
              </geometry>
             <material>
				<script>
					<uri>file://media/materials/scripts/gazebo.material</uri>
					<name>Gazebo/Red</name>
				</script>
			</material>
            </visual>
          </link>
      <joint type="fixed" name="connector_spinnaker_hinge">
        <pose>0 0 0.03 0 0 0</pose>
        <child>spinnaker</child>
        <parent>connector</parent>
        <axis>
          <xyz>1 1 1</xyz>
        </axis>
      </joint>
          
          
          
           <link name="front_left_wheel">
        <pose>0.15 0.12 0.063 0 1.5707 1.5707</pose>
      <inertial>
        <mass>2.6357</mass>
        <pose>0 0 0 0 0 0</pose>
        <inertia>
          <ixx>0.0246688</ixx>
          <ixy>0</ixy>
          <ixz>0</ixz>
          <iyy>0.0246688</iyy>
          <iyz>0</iyz>
          <izz>0.0441058</izz>
        </inertia>
      </inertial>
        <collision name="front_left_wheel_collision">
          <geometry>
            <cylinder>
              <radius>.063</radius>
              <length>.07</length>
            </cylinder>
          </geometry>
	<surface>
          <friction>
            <ode>
              <mu>100000.0</mu>
              <mu2>100000.0</mu2>
              <slip1>0.0</slip1>
              <slip2>0.0</slip2>
            </ode>
          </friction>
        </surface>
        </collision>
        <visual name="front_left_wheel">
          <geometry>
            <cylinder>
              <radius>.063</radius>
              <length>.07</length>
            </cylinder>
          </geometry>
        </visual>
      </link>
   <joint name="front_left_joint" type="revolute">
      <sensor name="front_left_sensor" type="force_torque"><force_torque></force_torque></sensor>
      <parent>chassis</parent>
      <child>front_left_wheel</child>
      <axis>
        <xyz>0 1 0</xyz>
        <use_parent_model_frame>true</use_parent_model_frame>
      </axis>
      <physics>
        <provide_feedback>true</provide_feedback>
        <ode>
          <limit>
            <cfm>0.000000</cfm>
            <erp>0.900000</erp>
          </limit>
        </ode>
      </physics>
    </joint>
      



      <link name="front_right_wheel">
        <pose>0.15 -0.12 0.063 0 1.5707 1.5707</pose>
      <inertial>
        <mass>2.6357</mass>
        <pose>0 0 0 0 0 0</pose>
        <inertia>
          <ixx>0.0246688</ixx>
          <ixy>0</ixy>
          <ixz>0</ixz>
          <iyy>0.0246688</iyy>
          <iyz>0</iyz>
          <izz>0.0441058</izz>
        </inertia>
      </inertial>
        <collision name="front_right_wheel_collision">
          <geometry>
            <cylinder>
              <radius>.063</radius>
              <length>.07</length>
            </cylinder>
          </geometry>
	<surface>
          <friction>
            <ode>
              <mu>100000.0</mu>
              <mu2>100000.0</mu2>
              <slip1>0.0</slip1>
              <slip2>0.0</slip2>
            </ode>
          </friction>
        </surface>
        </collision>
        <visual name="front_right_wheel">
          <geometry>
            <cylinder>
              <radius>.063</radius>
              <length>.07</length>
            </cylinder>
          </geometry>
        </visual>
      </link>
    <joint name="front_right_joint" type="revolute">
      <sensor name="front_right_sensor" type="force_torque"><force_torque></force_torque></sensor>
      <parent>chassis</parent>
      <child>front_right_wheel</child>
      <axis>
        <xyz>0 1 0</xyz>
        <use_parent_model_frame>true</use_parent_model_frame>
      </axis>
      <physics>
        <provide_feedback>true</provide_feedback>
        <ode>
          <limit>
            <cfm>0.000000</cfm>
            <erp>0.900000</erp>
          </limit>
        </ode>
      </physics>
    </joint>

   
         <link name="left_wheel_middle">
        <pose>0.0 0.09 0.07 0 1.5707 1.5707</pose>
        <collision name="collision">
          <geometry>
            <cylinder>
              <radius>.063</radius>
              <length>.07</length>
            </cylinder>
          </geometry>
        </collision>
        <visual name="visual">
          <geometry>
            <cylinder>
              <radius>.063</radius>
              <length>.07</length>
            </cylinder>
          </geometry>
        </visual>
      </link>
      

      <link name="right_wheel_middle">
        <pose>0.0 -0.09 0.07 0 1.5707 1.5707</pose>
        <collision name="collision">
          <geometry>
            <cylinder>
              <radius>.063</radius>
              <length>.07</length>
            </cylinder>
          </geometry>
        </collision>
        <visual name="visual">
          <geometry>
            <cylinder>
              <radius>.063</radius>
              <length>.07</length>
            </cylinder>
          </geometry>
        </visual>
      </link>


      
       <link name="back_left_wheel">
        <pose>-0.15 0.12 0.063 0 1.5707 1.5707</pose>
      <inertial>
        <mass>2.6357</mass>
        <pose>0 0 0 0 0 0</pose>
        <inertia>
          <ixx>0.0246688</ixx>
          <ixy>0</ixy>
          <ixz>0</ixz>
          <iyy>0.0246688</iyy>
          <iyz>0</iyz>
          <izz>0.0441058</izz>
        </inertia>
      </inertial>
        <collision name="back_left_wheel_collision">
          <geometry>
            <cylinder>
              <radius>.063</radius>
              <length>.07</length>
            </cylinder>
          </geometry>
	<surface>
          <friction>
            <ode>
              <mu>100000.0</mu>
              <mu2>100000.0</mu2>
              <slip1>0.0</slip1>
              <slip2>0.0</slip2>
            </ode>
          </friction>
        </surface>
        </collision>
        <visual name="back_left_wheel">
          <geometry>
            <cylinder>
              <radius>.063</radius>
              <length>.07</length>
            </cylinder>
          </geometry>
        </visual>
      </link>
      <joint name="back_left_joint" type="revolute">
      <sensor name="back_left_sensor" type="force_torque"><force_torque></force_torque></sensor>
      <parent>chassis</parent>
      <child>back_left_wheel</child>
      <axis>
        <xyz>0 1 0</xyz>
        <use_parent_model_frame>true</use_parent_model_frame>
      </axis>
      <physics>
        <provide_feedback>true</provide_feedback>
        <ode>
          <limit>
            <cfm>0.000000</cfm>
            <erp>0.900000</erp>
          </limit>
        </ode>
      </physics>
    </joint>

      
      <link name="back_right_wheel">
        <pose>-0.15 -0.12 0.063 0 1.5707 1.5707</pose>
      <inertial>
        <mass>2.6357</mass>
        <pose>0 0 0 0 0 0</pose>
        <inertia>
          <ixx>0.0246688</ixx>
          <ixy>0</ixy>
          <ixz>0</ixz>
          <iyy>0.0246688</iyy>
          <iyz>0</iyz>
          <izz>0.0441058</izz>
        </inertia>
      </inertial>
        <collision name="back_right_wheel_collision">
          <geometry>
            <cylinder>
              <radius>.063</radius>
              <length>.07</length>
            </cylinder>
          </geometry>
	<surface>
          <friction>
            <ode>
              <mu>100000.0</mu>
              <mu2>100000.0</mu2>
              <slip1>0.0</slip1>
              <slip2>0.0</slip2>
            </ode>
          </friction>
        </surface>
        </collision>
        <visual name="back_right_wheel">
          <geometry>
            <cylinder>
              <radius>.063</radius>
              <length>.07</length>
            </cylinder>
          </geometry>
        </visual>
      </link>
      <joint name="back_right_joint" type="revolute">
      <sensor name="back_right_sensor" type="force_torque"><force_torque></force_torque></sensor>
      <parent>chassis</parent>
      <child>back_right_wheel</child>
      <axis>
        <xyz>0 1 0</xyz>
        <use_parent_model_frame>true</use_parent_model_frame>
      </axis>
      <physics>
        <provide_feedback>true</provide_feedback>
        <ode>
          <limit>
            <cfm>0.000000</cfm>
            <erp>0.900000</erp>
          </limit>
        </ode>
      </physics>
    </joint>
      





          <joint type="fixed" name="left_wheel_middle_hinge">
        <pose>0 0 -0.03 0 0 0</pose>
        <child>left_wheel_middle</child>
        <parent>chassis</parent>
        <axis>
          <xyz>0 1 0</xyz>
        </axis>
      </joint>

      <joint type="fixed" name="right_wheel_middle_hinge">
        <pose>0 0 0.03 0 0 0</pose>
        <child>right_wheel_middle</child>
        <parent>chassis</parent>
        <axis>
          <xyz>0 1 0</xyz>
        </axis>
      </joint>


      


      

      
      
<link name='CameraMountRightXAxis_link'>
      <pose frame=''>0 0 0 0 0 0</pose>
      <inertial>
        <pose frame=''>0 0 0 0 0 0</pose>
        <mass>0.21</mass>
        <inertia>
          <ixx>3.61792</ixx>
          <ixy>-2.38095e-09</ixy>
          <ixz>0</ixz>
          <iyy>3.60464</iyy>
          <iyz>0</iyz>
          <izz>3.61794</izz>
        </inertia>
      </inertial>
      
      
 <!--       <collision name='CameraMountRightXAxis_link_collision'>
        <pose frame=''>0.2 0 0.2 0 0 0</pose>
        <geometry>
          <mesh>
            <scale>1 1 1</scale>
            <uri>model://TUM_Head/collisions/COL_VIZ_CameraMountRightXAxis_convex_hull.dae</uri>
          </mesh>
        </geometry>
      </collision>
      
      
    <collision name='CameraMountRightXAxis_link_fixed_joint_lump__cameraright_link_collision_1'>
        <pose frame=''>0.2 0 0.2 0 0 0</pose>
        <geometry>
          <mesh>
            <scale>1 1 1</scale>
            <uri>model://TUM_Head/collisions/COL_cameraright_convex_hull.dae</uri>
          </mesh>
        </geometry>
      </collision> -->
      
      <visual name='CameraMountRightXAxis_link_visual'>
        <pose frame=''>0.16 0.25 0.0 1.63 -1.5707963 0</pose>
        <geometry>
          <mesh>
            <scale>1 1 1</scale>
            <uri>model://TUM_Head/meshes/VIZ_CameraMountRightXAxis.dae</uri>
          </mesh>
        </geometry>
      </visual>
      
      <visual name='CameraMountRightXAxis_link_fixed_joint_lump__cameraright_link_visual_1'>
        <pose frame=''>0.16 0.25 0.0 1.63 -1.5707963 0</pose>
        <geometry>
          <mesh>
            <scale>1 1 1</scale>
            <uri>model://TUM_Head/meshes/cameraright.dae</uri>
          </mesh>
        </geometry>
      </visual>
      
      <gravity>1</gravity>
      
      <velocity_decay/>
      
      <self_collide>0</self_collide>
      
      
      
      <sensor name='camera_dvs_left' type='camera'>
        <visualize>1</visualize>
        <camera name='camera_dvs_left'>
          <horizontal_fov>2.44346</horizontal_fov>
          <image>
            <width>128</width>
            <height>40</height>
          </image>
          <clip>
            <near>0.1</near>
            <far>5</far>
          </clip>
        </camera>
        <always_on>1</always_on>
        <update_rate>200</update_rate>
        <visualize>0</visualize>
        <plugin name='camera_controller' filename='libgazebo_dvs_plugin.so'>
          <cameraName>edvs</cameraName>
          <robotNamespace>spikerobot</robotNamespace>
          <eventThreshold>10</eventThreshold>
          <cameraInfoTopicName>camera_info</cameraInfoTopicName>
        </plugin>
        <pose frame=''> 0.15 0 0.25 0 0 0 </pose>
      </sensor>
    </link>
    
    
    <joint name='CameraMountRightXAxis_joint' type='fixed'>
      <child>CameraMountRightXAxis_link</child>
      <parent>chassis</parent>
      <axis>
        <xyz>1 0 0</xyz>
        <limit>
          <lower>-1.5708</lower>
          <upper>1.5708</upper>
          <effort>100</effort>
          <velocity>1</velocity>
        </limit>
        <dynamics>
          <damping>1</damping>
          <friction>0</friction>
          <spring_reference>0</spring_reference>
          <spring_stiffness>0</spring_stiffness>
        </dynamics>
        <use_parent_model_frame>1</use_parent_model_frame>
      </axis>
    </joint>


    <plugin name="husky_diff_controller" filename="libhusky_gazebo_plugins.so">
      <alwaysOn>true</alwaysOn>
      <updateRate>100.0</updateRate>
      <backLeftJoint>back_left_joint</backLeftJoint>
      <backRightJoint>back_right_joint</backRightJoint>
      <frontLeftJoint>front_left_joint</frontLeftJoint>
      <frontRightJoint>front_right_joint</frontRightJoint>
      <wheelSeparation>0.5709</wheelSeparation>
      <wheelDiameter>0.3555</wheelDiameter>
      <torque>35</torque>
    </plugin>
      

    
      
  </model>
</sdf>
